Workbook

Sheet ENERO
C1: =SUM(C3:C7) -> 0
B2: Ingresos | C2: =100%-C1 -> 1
B3: Fijos | C3: =+C11/C10 -> 0
B4: Variables | C4: =+C12/C10 -> 0
B5: Inversion | C5: =+C15/C10 -> 0
B6: Ocio | C6: =+C13/C10 -> 0
B7: Ahorro | C7: =+C14/C10 -> 0
B9: CONTROL DE ENERO | I9: INGRESOS | J9: Intereses Recibidos
B10: Ingresos | C10: =+J16 -> 5000000 | J10: 5000000
B11: Fijos | C11: =+SUMIFS($G$20:$G$48,$E$20:$E$48,$B$11) -> 0
B12: Variables | C12: =+SUMIFS($G$20:$G$47,$E$20:$E$47,$B$12) -> 0
B13: Ocio | C13: =+SUMIFS($G$20:$G$48,$E$20:$E$48,$B$13) -> 0
B14: Ahorro | C14: =+SUMIFS($G$20:$G$48,$E$20:$E$48,$B$14) -> 0
B15: Inversion | C15: =+SUMIFS($G$20:$G$48,$E$20:$E$48,$B$15) -> 0
B16: Total Gastado | I16: TOTAL | J16: =+SUM(J10:J15) -> 5000000
B17: =+SUM(C11:C15) -> 0
B19: Fecha | C19: Medio de pago | D19: Descripción | E19: Categoría | F19: Presupuestado | G19: Gastado
E20: Fijos
E21: Variables
E22: Ahorro | I22: Ahorro / Inversion | J22: Intereses Recibidos
E23: Inversion | I23: Trii
E24: Ocio | I24: Uala
E25: Fijos | I25: Nubank
E26: Inversion
E27: Variables
E28: Ocio
E29: Ahorro | I29: TOTAL | J29: =+SUM(J23:J28) -> 0
E30: Ocio
E31: Fijos
E32: Inversion
E33: Variables
E34: Ocio
E35: Ahorro | I35: DEUDA | J35: VALOR | K35: PAGADO | L35: NUEVO VALOR
E36: Ocio | L36: =+J36+K36 -> 0
E37: Fijos | L37: =+J37+K37 -> 0
E38: Inversion | L38: =+J38+K38 -> 0
E39: Variables | L39: =+J39+K39 -> 0
E40: Ocio | L40: =+J40+K40 -> 0
E41: Ahorro | L41: =+J41+K41 -> 0
E42: Ocio | L42: =+J42+K42 -> 0
...

Sheet FEBRERO
C1: =SUM(C3:C7) -> 0
B2: Ingresos | C2: =100%-C1 -> 1
B3: Fijos | C3: =+C11/C10 -> 0
B4: Variables | C4: =+C12/C10 -> 0
B5: Inversion | C5: =+C15/C10 -> 0
B6: Ocio | C6: =+C13/C10 -> 0
B7: Ahorro | C7: =+C14/C10 -> 0
B9: CONTROL DE FEBRERO | I9: INGRESOS | J9: Intereses Recibidos
B10: Ingresos | C10: =+J16 -> 5000000 | J10: 5000000
B11: Fijos | C11: =+SUMIFS($G$20:$G$48,$E$20:$E$48,$B$11) -> 0
B12: Variables | C12: =+SUMIFS($G$20:$G$47,$E$20:$E$47,$B$12) -> 0
B13: Ocio | C13: =+SUMIFS($G$20:$G$48,$E$20:$E$48,$B$13) -> 0
B14: Ahorro | C14: =+SUMIFS($G$20:$G$48,$E$20:$E$48,$B$14) -> 0
B15: Inversion | C15: =+SUMIFS($G$20:$G$48,$E$20:$E$48,$B$15) -> 0
B16: Total Gastado | I16: TOTAL | J16: =+SUM(J10:J15) -> 5000000
B17: =+SUM(C11:C15) -> 0
B19: Fecha | C19: Medio de pago | D19: Descripción | E19: Categoría | F19: Presupuestado | G19: Gastado
E20: Fijos
E21: Variables
E22: Ahorro | I22: Ahorro / Inversion | J22: Intereses Recibidos
E23: Inversion | I23: =+ENERO!I23 -> Trii
E24: Ocio | I24: =+ENERO!I24 -> Uala
E25: Fijos | I25: =+ENERO!I25 -> Nubank
E26: Inversion | I26: =+ENERO!I26 -> 0
E27: Variables | I27: =+ENERO!I27 -> 0
E28: Ocio | I28: =+ENERO!I28 -> 0
E29: Ahorro | I29: TOTAL | J29: =+SUM(J23:J28) -> 0
E30: Ocio
E31: Fijos
E32: Inversion
E33: Variables
E34: Ocio | I34: DEUDA | J34: VALOR | K34: PAGADO | L34: NUEVO VALOR
E35: Ahorro | I35: =+ENERO!I36 -> 0 | J35: =+ENERO!L36 -> 0 | L35: =+J35+K35 -> 0
E36: Ocio | I36: =+ENERO!I37 -> 0 | J36: =+ENERO!L37 -> 0 | L36: =+J36+K36 -> 0
E37: Fijos | I37: =+ENERO!I38 -> 0 | J37: =+ENERO!L38 -> 0 | L37: =+J37+K37 -> 0
E38: Inversion | I38: =+ENERO!I39 -> 0 | J38: =+ENERO!L39 -> 0 | L38: =+J38+K38 -> 0
E39: Variables | I39: =+ENERO!I40 -> 0 | J39: =+ENERO!L40 -> 0 | L39: =+J39+K39 -> 0
E40: Ocio | I40: =+ENERO!I41 -> 0 | J40: =+ENERO!L41 -> 0 | L40: =+J40+K40 -> 0
E41: Ahorro | I41: =+ENERO!I42 -> 0 | J41: =+ENERO!L42 -> 0 | L41: =+J41+K41 -> 0
E42: Ocio | I42: =+ENERO!I43 -> 0 | J42: =+ENERO!L43 -> 0 | L42: =+J42+K42 -> 0
...

Sheet MARZO
C1: =SUM(C3:C7) -> 0
B2: Ingresos | C2: =100%-C1 -> 1
B3: Fijos | C3: =+C11/C10 -> 0
B4: Variables | C4: =+C12/C10 -> 0
B5: Inversion | C5: =+C15/C10 -> 0
B6: Ocio | C6: =+C13/C10 -> 0
B7: Ahorro | C7: =+C14/C10 -> 0
B9: CONTROL DE MARZO | I9: INGRESOS | J9: Intereses Recibidos
B10: Ingresos | C10: =+J16 -> 5000000 | J10: 5000000
B11: Fijos | C11: =+SUMIFS($G$20:$G$48,$E$20:$E$48,$B$11) -> 0
B12: Variables | C12: =+SUMIFS($G$20:$G$47,$E$20:$E$47,$B$12) -> 0
B13: Ocio | C13: =+SUMIFS($G$20:$G$48,$E$20:$E$48,$B$13) -> 0
B14: Ahorro | C14: =+SUMIFS($G$20:$G$48,$E$20:$E$48,$B$14) -> 0
B15: Inversion | C15: =+SUMIFS($G$20:$G$48,$E$20:$E$48,$B$15) -> 0
B16: Total Gastado | I16: TOTAL | J16: =+SUM(J10:J15) -> 5000000
B17: =+SUM(C11:C15) -> 0
B19: Fecha | C19: Medio de pago | D19: Descripción | E19: Categoría | F19: Presupuestado | G19: Gastado
E20: Fijos
E21: Variables
E22: Ahorro | I22: Ahorro / Inversion | J22: Intereses Recibidos
E23: Inversion | I23: =+FEBRERO!I23 -> Trii
E24: Ocio | I24: =+FEBRERO!I24 -> Uala
E25: Fijos | I25: =+FEBRERO!I25 -> Nubank
E26: Inversion | I26: =+FEBRERO!I26 -> 0
E27: Variables | I27: =+FEBRERO!I27 -> 0
E28: Ocio | I28: =+FEBRERO!I28 -> 0
E29: Ahorro | I29: TOTAL | J29: =+SUM(J23:J28) -> 0
E30: Ocio
E31: Fijos
E32: Inversion
E33: Variables
E34: Ocio | I34: DEUDA | J34: VALOR | K34: PAGADO | L34: NUEVO VALOR
E35: Ahorro | I35: =+FEBRERO!I35 -> 0 | J35: =+FEBRERO!L35 -> 0 | L35: =+J35+K35 -> 0
E36: Ocio | I36: =+FEBRERO!I36 -> 0 | J36: =+FEBRERO!L36 -> 0 | L36: =+J36+K36 -> 0
E37: Fijos | I37: =+FEBRERO!I37 -> 0 | J37: =+FEBRERO!L37 -> 0 | L37: =+J37+K37 -> 0
E38: Inversion | I38: =+FEBRERO!I38 -> 0 | J38: =+FEBRERO!L38 -> 0 | L38: =+J38+K38 -> 0
E39: Variables | I39: =+FEBRERO!I39 -> 0 | J39: =+FEBRERO!L39 -> 0 | L39: =+J39+K39 -> 0
E40: Ocio | I40: =+FEBRERO!I40 -> 0 | J40: =+FEBRERO!L40 -> 0 | L40: =+J40+K40 -> 0
E41: Ahorro | I41: =+FEBRERO!I41 -> 0 | J41: =+FEBRERO!L41 -> 0 | L41: =+J41+K41 -> 0
E42: Ocio | I42: =+FEBRERO!I42 -> 0 | J42: =+FEBRERO!L42 -> 0 | L42: =+J42+K42 -> 0
...

Sheet ABRIL
C1: =SUM(C3:C7) -> 0
B2: Ingresos | C2: =100%-C1 -> 1
B3: Fijos | C3: =+C11/C10 -> 0
B4: Variables | C4: =+C12/C10 -> 0
B5: Inversion | C5: =+C15/C10 -> 0
B6: Ocio | C6: =+C13/C10 -> 0
B7: Ahorro | C7: =+C14/C10 -> 0
B9: CONTROL DE ABRIL | I9: INGRESOS | J9: Intereses Recibidos
B10: Ingresos | C10: =+J16 -> 5000000 | J10: 5000000
B11: Fijos | C11: =+SUMIFS($G$20:$G$48,$E$20:$E$48,$B$11) -> 0
B12: Variables | C12: =+SUMIFS($G$20:$G$47,$E$20:$E$47,$B$12) -> 0
B13: Ocio | C13: =+SUMIFS($G$20:$G$48,$E$20:$E$48,$B$13) -> 0
B14: Ahorro | C14: =+SUMIFS($G$20:$G$48,$E$20:$E$48,$B$14) -> 0
B15: Inversion | C15: =+SUMIFS($G$20:$G$48,$E$20:$E$48,$B$15) -> 0
B16: Total Gastado | I16: TOTAL | J16: =+SUM(J10:J15) -> 5000000
B17: =+SUM(C11:C15) -> 0
B19: Fecha | C19: Medio de pago | D19: Descripción | E19: Categoría | F19: Presupuestado | G19: Gastado
E20: Fijos
E21: Variables
E22: Ahorro | I22: Ahorro / Inversion | J22: Intereses Recibidos
E23: Inversion | I23: =+MARZO!I23 -> Trii
E24: Ocio | I24: =+MARZO!I24 -> Uala
E25: Fijos | I25: =+MARZO!I25 -> Nubank
E26: Inversion | I26: =+MARZO!I26 -> 0
E27: Variables | I27: =+MARZO!I27 -> 0
E28: Ocio | I28: =+MARZO!I28 -> 0
E29: Ahorro | I29: TOTAL | J29: =+SUM(J23:J28) -> 0
E30: Ocio
E31: Fijos
E32: Inversion
E33: Variables
E34: Ocio | I34: DEUDA | J34: VALOR | K34: PAGADO | L34: NUEVO VALOR
E35: Ahorro | I35: {=+MARZO!I35:I42} -> 0 | J35: =+MARZO!L35 -> 0 | L35: =+J35+K35 -> 0
E36: Ocio | I36: 0 | J36: =+MARZO!L36 -> 0 | L36: =+J36+K36 -> 0
E37: Fijos | I37: 0 | J37: =+MARZO!L37 -> 0 | L37: =+J37+K37 -> 0
E38: Inversion | I38: 0 | J38: =+MARZO!L38 -> 0 | L38: =+J38+K38 -> 0
E39: Variables | I39: 0 | J39: =+MARZO!L39 -> 0 | L39: =+J39+K39 -> 0
E40: Ocio | I40: 0 | J40: =+MARZO!L40 -> 0 | L40: =+J40+K40 -> 0
E41: Ahorro | I41: 0 | J41: =+MARZO!L41 -> 0 | L41: =+J41+K41 -> 0
E42: Ocio | I42: 0 | J42: =+MARZO!L42 -> 0 | L42: =+J42+K42 -> 0
...

Sheet MAYO
C1: =SUM(C3:C7) -> 0
B2: Ingresos | C2: =100%-C1 -> 1
B3: Fijos | C3: =+C11/C10 -> 0
B4: Variables | C4: =+C12/C10 -> 0
B5: Inversion | C5: =+C15/C10 -> 0
B6: Ocio | C6: =+C13/C10 -> 0
B7: Ahorro | C7: =+C14/C10 -> 0
B9: CONTROL DE MAYO | I9: INGRESOS | J9: Intereses Recibidos
B10: Ingresos | C10: =+J16 -> 5000000 | J10: 5000000
B11: Fijos | C11: =+SUMIFS($G$20:$G$48,$E$20:$E$48,$B$11) -> 0
B12: Variables | C12: =+SUMIFS($G$20:$G$47,$E$20:$E$47,$B$12) -> 0
B13: Ocio | C13: =+SUMIFS($G$20:$G$48,$E$20:$E$48,$B$13) -> 0
B14: Ahorro | C14: =+SUMIFS($G$20:$G$48,$E$20:$E$48,$B$14) -> 0
B15: Inversion | C15: =+SUMIFS($G$20:$G$48,$E$20:$E$48,$B$15) -> 0
B16: Total Gastado | I16: TOTAL | J16: =+SUM(J10:J15) -> 5000000
B17: =+SUM(C11:C15) -> 0
B19: Fecha | C19: Medio de pago | D19: Descripción | E19: Categoría | F19: Presupuestado | G19: Gastado
E20: Fijos
E21: Variables
E22: Ahorro | I22: Ahorro / Inversion | J22: Intereses Recibidos
E23: Inversion | I23: =+ABRIL!I23 -> Trii
E24: Ocio | I24: =+ABRIL!I24 -> Uala
E25: Fijos | I25: =+ABRIL!I25 -> Nubank
E26: Inversion | I26: =+ABRIL!I26 -> 0
E27: Variables | I27: =+ABRIL!I27 -> 0
E28: Ocio | I28: =+ABRIL!I28 -> 0
E29: Ahorro | I29: TOTAL | J29: =+SUM(J23:J28) -> 0
E30: Ocio
E31: Fijos
E32: Inversion
E33: Variables
E34: Ocio | I34: DEUDA | J34: VALOR | K34: PAGADO | L34: NUEVO VALOR
E35: Ahorro | I35: =+ABRIL!I35 -> 0 | J35: =+ABRIL!L35 -> 0 | L35: =+J35+K35 -> 0
E36: Ocio | I36: =+ABRIL!I36 -> 0 | J36: =+ABRIL!L36 -> 0 | L36: =+J36+K36 -> 0
E37: Fijos | I37: =+ABRIL!I37 -> 0 | J37: =+ABRIL!L37 -> 0 | L37: =+J37+K37 -> 0
E38: Inversion | I38: =+ABRIL!I38 -> 0 | J38: =+ABRIL!L38 -> 0 | L38: =+J38+K38 -> 0
E39: Variables | I39: =+ABRIL!I39 -> 0 | J39: =+ABRIL!L39 -> 0 | L39: =+J39+K39 -> 0
E40: Ocio | I40: =+ABRIL!I40 -> 0 | J40: =+ABRIL!L40 -> 0 | L40: =+J40+K40 -> 0
E41: Ahorro | I41: =+ABRIL!I41 -> 0 | J41: =+ABRIL!L41 -> 0 | L41: =+J41+K41 -> 0
E42: Ocio | I42: =+ABRIL!I42 -> 0 | J42: =+ABRIL!L42 -> 0 | L42: =+J42+K42 -> 0
...

Sheet JUNIO
C1: =SUM(C3:C7) -> 0
B2: Ingresos | C2: =100%-C1 -> 1
B3: Fijos | C3: =+C11/C10 -> 0
B4: Variables | C4: =+C12/C10 -> 0
B5: Inversion | C5: =+C15/C10 -> 0
B6: Ocio | C6: =+C13/C10 -> 0
B7: Ahorro | C7: =+C14/C10 -> 0
B9: CONTROL DE JUNIO | I9: INGRESOS | J9: Intereses Recibidos
B10: Ingresos | C10: =+J16 -> 5000000 | J10: 5000000
B11: Fijos | C11: =+SUMIFS($G$20:$G$48,$E$20:$E$48,$B$11) -> 0
B12: Variables | C12: =+SUMIFS($G$20:$G$47,$E$20:$E$47,$B$12) -> 0
B13: Ocio | C13: =+SUMIFS($G$20:$G$48,$E$20:$E$48,$B$13) -> 0
B14: Ahorro | C14: =+SUMIFS($G$20:$G$48,$E$20:$E$48,$B$14) -> 0
B15: Inversion | C15: =+SUMIFS($G$20:$G$48,$E$20:$E$48,$B$15) -> 0
B16: Total Gastado | I16: TOTAL | J16: =+SUM(J10:J15) -> 5000000
B17: =+SUM(C11:C15) -> 0
B19: Fecha | C19: Medio de pago | D19: Descripción | E19: Categoría | F19: Presupuestado | G19: Gastado
E20: Fijos
E21: Variables
E22: Ahorro | I22: Ahorro / Inversion | J22: Intereses Recibidos
E23: Inversion | I23: =+MAYO!I23 -> Trii
E24: Ocio | I24: =+MAYO!I24 -> Uala
E25: Fijos | I25: =+MAYO!I25 -> Nubank
E26: Inversion | I26: =+MAYO!I26 -> 0
E27: Variables | I27: =+MAYO!I27 -> 0
E28: Ocio | I28: =+MAYO!I28 -> 0
E29: Ahorro | I29: TOTAL | J29: =+SUM(J23:J28) -> 0
E30: Ocio
E31: Fijos
E32: Inversion
E33: Variables
E34: Ocio | I34: DEUDA | J34: VALOR | K34: PAGADO | L34: NUEVO VALOR
E35: Ahorro | I35: =+MAYO!I35 -> 0 | J35: =+MAYO!L35 -> 0 | L35: =+J35+K35 -> 0
E36: Ocio | I36: =+MAYO!I36 -> 0 | J36: =+MAYO!L36 -> 0 | L36: =+J36+K36 -> 0
E37: Fijos | I37: =+MAYO!I37 -> 0 | J37: =+MAYO!L37 -> 0 | L37: =+J37+K37 -> 0
E38: Inversion | I38: =+MAYO!I38 -> 0 | J38: =+MAYO!L38 -> 0 | L38: =+J38+K38 -> 0
E39: Variables | I39: =+MAYO!I39 -> 0 | J39: =+MAYO!L39 -> 0 | L39: =+J39+K39 -> 0
E40: Ocio | I40: =+MAYO!I40 -> 0 | J40: =+MAYO!L40 -> 0 | L40: =+J40+K40 -> 0
E41: Ahorro | I41: =+MAYO!I41 -> 0 | J41: =+MAYO!L41 -> 0 | L41: =+J41+K41 -> 0
E42: Ocio | I42: =+MAYO!I42 -> 0 | J42: =+MAYO!L42 -> 0 | L42: =+J42+K42 -> 0
...

Sheet JULIO
C1: =SUM(C3:C7) -> 0
B2: Ingresos | C2: =100%-C1 -> 1
B3: Fijos | C3: =+C11/C10 -> 0
B4: Variables | C4: =+C12/C10 -> 0
B5: Inversion | C5: =+C15/C10 -> 0
B6: Ocio | C6: =+C13/C10 -> 0
B7: Ahorro | C7: =+C14/C10 -> 0
B9: CONTROL DE JULIO | I9: INGRESOS | J9: Intereses Recibidos
B10: Ingresos | C10: =+J16 -> 5000000 | J10: 5000000
B11: Fijos | C11: =+SUMIFS($G$20:$G$48,$E$20:$E$48,$B$11) -> 0
B12: Variables | C12: =+SUMIFS($G$20:$G$47,$E$20:$E$47,$B$12) -> 0
B13: Ocio | C13: =+SUMIFS($G$20:$G$48,$E$20:$E$48,$B$13) -> 0
B14: Ahorro | C14: =+SUMIFS($G$20:$G$48,$E$20:$E$48,$B$14) -> 0
B15: Inversion | C15: =+SUMIFS($G$20:$G$48,$E$20:$E$48,$B$15) -> 0
B16: Total Gastado | I16: TOTAL | J16: =+SUM(J10:J15) -> 5000000
B17: =+SUM(C11:C15) -> 0
B19: Fecha | C19: Medio de pago | D19: Descripción | E19: Categoría | F19: Presupuestado | G19: Gastado
D20: Arriendo | E20: Fijos
D21: Agua | E21: Fijos
D22: Ahorro mensual | E22: Ahorro | I22: Ahorro / Inversion | J22: Intereses Recibidos
D23: T Davivienda | E23: Fijos | I23: =+JUNIO!I23 -> Trii
D24: T NuBank | E24: Fijos | I24: =+JUNIO!I24 -> Uala
D25: Crédito del papá | E25: Fijos | I25: =+JUNIO!I25 -> Nubank
D26: Celular | E26: Fijos | I26: =+JUNIO!I26 -> 0
D27: Gas | E27: Fijos | I27: =+JUNIO!I27 -> 0
D28: Internet | E28: Fijos | I28: =+JUNIO!I28 -> 0
D29: Energía | E29: Fijos | I29: TOTAL | J29: =+SUM(J23:J28) -> 0
D30: Mercado | E30: Fijos
D31: Inges sobrinos | E31: Fijos
D32: Almuerzos | E32: Fijos
D33: Saqué del ahorro para X | E33: Ahorro
E34: Ocio | I34: DEUDA | J34: VALOR | K34: PAGADO | L34: NUEVO VALOR
E35: Ahorro | I35: =+JUNIO!I35 -> 0 | J35: =+JUNIO!J35 -> 0 | L35: =+J35+K35 -> 0
E36: Ocio | I36: =+JUNIO!I36 -> 0 | J36: =+JUNIO!J36 -> 0 | L36: =+J36+K36 -> 0
E37: Fijos | I37: =+JUNIO!I37 -> 0 | J37: =+JUNIO!J37 -> 0 | L37: =+J37+K37 -> 0
E38: Inversion | I38: =+JUNIO!I38 -> 0 | J38: =+JUNIO!J38 -> 0 | L38: =+J38+K38 -> 0
E39: Variables | I39: =+JUNIO!I39 -> 0 | J39: =+JUNIO!J39 -> 0 | L39: =+J39+K39 -> 0
E40: Ocio | I40: =+JUNIO!I40 -> 0 | J40: =+JUNIO!J40 -> 0 | L40: =+J40+K40 -> 0
E41: Ahorro | I41: =+JUNIO!I41 -> 0 | J41: =+JUNIO!J41 -> 0 | L41: =+J41+K41 -> 0
E42: Ocio | I42: =+JUNIO!I42 -> 0 | J42: =+JUNIO!J42 -> 0 | L42: =+J42+K42 -> 0
...

Sheet AGOSTO
C1: =SUM(C3:C7) -> 0
B2: Ingresos | C2: =100%-C1 -> 1
B3: Fijos | C3: =+C11/C10 -> 0
B4: Variables | C4: =+C12/C10 -> 0
B5: Inversion | C5: =+C15/C10 -> 0
B6: Ocio | C6: =+C13/C10 -> 0
B7: Ahorro | C7: =+C14/C10 -> 0
B9: CONTROL DE AGOSTO | I9: INGRESOS | J9: Intereses Recibidos
B10: Ingresos | C10: =+J16 -> 5000000 | J10: 5000000
B11: Fijos | C11: =+SUMIFS($G$20:$G$48,$E$20:$E$48,$B$11) -> 0
B12: Variables | C12: =+SUMIFS($G$20:$G$47,$E$20:$E$47,$B$12) -> 0
B13: Ocio | C13: =+SUMIFS($G$20:$G$48,$E$20:$E$48,$B$13) -> 0
B14: Ahorro | C14: =+SUMIFS($G$20:$G$48,$E$20:$E$48,$B$14) -> 0
B15: Inversion | C15: =+SUMIFS($G$20:$G$48,$E$20:$E$48,$B$15) -> 0
B16: Total Gastado | I16: TOTAL | J16: =+SUM(J10:J15) -> 5000000
B17: =+SUM(C11:C15) -> 0
B19: Fecha | C19: Medio de pago | D19: Descripción | E19: Categoría | F19: Presupuestado | G19: Gastado
E20: Fijos
E21: Fijos
E22: Ahorro | I22: Ahorro / Inversion | J22: Intereses Recibidos
E23: Fijos | I23: =+JULIO!I23 -> Trii
E24: Fijos | I24: =+JULIO!I24 -> Uala
E25: Fijos | I25: =+JULIO!I25 -> Nubank
E26: Fijos | I26: =+JULIO!I26 -> 0
E27: Fijos | I27: =+JULIO!I27 -> 0
E28: Fijos | I28: =+JULIO!I28 -> 0
E29: Fijos | I29: TOTAL | J29: =+SUM(J23:J28) -> 0
E30: Fijos
E31: Fijos
E32: Fijos
E33: Variables
E34: Ocio | I34: DEUDA | J34: VALOR | K34: PAGADO | L34: NUEVO VALOR
E35: Ahorro | I35: =+JULIO!I35 -> 0 | J35: =+JULIO!J35 -> 0 | L35: =+J35+K35 -> 0
E36: Ocio | I36: =+JULIO!I36 -> 0 | J36: =+JULIO!J36 -> 0 | L36: =+J36+K36 -> 0
E37: Fijos | I37: =+JULIO!I37 -> 0 | J37: =+JULIO!J37 -> 0 | L37: =+J37+K37 -> 0
E38: Inversion | I38: =+JULIO!I38 -> 0 | J38: =+JULIO!J38 -> 0 | L38: =+J38+K38 -> 0
E39: Variables | I39: =+JULIO!I39 -> 0 | J39: =+JULIO!J39 -> 0 | L39: =+J39+K39 -> 0
E40: Ocio | I40: =+JULIO!I40 -> 0 | J40: =+JULIO!J40 -> 0 | L40: =+J40+K40 -> 0
E41: Ahorro | I41: =+JULIO!I41 -> 0 | J41: =+JULIO!J41 -> 0 | L41: =+J41+K41 -> 0
E42: Ocio | I42: =+JULIO!I42 -> 0 | J42: =+JULIO!J42 -> 0 | L42: =+J42+K42 -> 0
...

Sheet SEPTIEMBRE
C1: =SUM(C3:C7) -> 0
B2: Ingresos | C2: =100%-C1 -> 1
B3: Fijos | C3: =+C11/C10 -> 0
B4: Variables | C4: =+C12/C10 -> 0
B5: Inversion | C5: =+C15/C10 -> 0
B6: Ocio | C6: =+C13/C10 -> 0
B7: Ahorro | C7: =+C14/C10 -> 0
B9: CONTROL DE SEPTIEMBRE | I9: INGRESOS | J9: Intereses Recibidos
B10: Ingresos | C10: =+J16 -> 5000000 | J10: 5000000
B11: Fijos | C11: =+SUMIFS($G$20:$G$48,$E$20:$E$48,$B$11) -> 0
B12: Variables | C12: =+SUMIFS($G$20:$G$47,$E$20:$E$47,$B$12) -> 0
B13: Ocio | C13: =+SUMIFS($G$20:$G$48,$E$20:$E$48,$B$13) -> 0
B14: Ahorro | C14: =+SUMIFS($G$20:$G$48,$E$20:$E$48,$B$14) -> 0
B15: Inversion | C15: =+SUMIFS($G$20:$G$48,$E$20:$E$48,$B$15) -> 0
B16: Total Gastado | I16: TOTAL | J16: =+SUM(J10:J15) -> 5000000
B17: =+SUM(C11:C15) -> 0
B19: Fecha | C19: Medio de pago | D19: Descripción | E19: Categoría | F19: Presupuestado | G19: Gastado
E20: Fijos
E21: Fijos
E22: Ahorro | I22: Ahorro / Inversion | J22: Intereses Recibidos
E23: Fijos | I23: =+AGOSTO!I23 -> Trii
E24: Fijos | I24: =+AGOSTO!I24 -> Uala
E25: Fijos | I25: =+AGOSTO!I25 -> Nubank
E26: Fijos | I26: =+AGOSTO!I26 -> 0
E27: Fijos | I27: =+AGOSTO!I27 -> 0
E28: Fijos | I28: =+AGOSTO!I28 -> 0
E29: Fijos | I29: TOTAL | J29: =+SUM(J23:J28) -> 0
E30: Fijos
E31: Fijos
E32: Fijos
E33: Variables
E34: Ocio | I34: DEUDA | J34: VALOR | K34: PAGADO | L34: NUEVO VALOR
E35: Ahorro | I35: =+AGOSTO!I35 -> 0 | J35: =+AGOSTO!L35 -> 0 | L35: =+J35+K35 -> 0
E36: Ocio | I36: =+AGOSTO!I36 -> 0 | J36: =+AGOSTO!L36 -> 0 | L36: =+J36+K36 -> 0
E37: Fijos | I37: =+AGOSTO!I37 -> 0 | J37: =+AGOSTO!L37 -> 0 | L37: =+J37+K37 -> 0
E38: Inversion | I38: =+AGOSTO!I38 -> 0 | J38: =+AGOSTO!L38 -> 0 | L38: =+J38+K38 -> 0
E39: Variables | I39: =+AGOSTO!I39 -> 0 | J39: =+AGOSTO!L39 -> 0 | L39: =+J39+K39 -> 0
E40: Ocio | I40: =+AGOSTO!I40 -> 0 | J40: =+AGOSTO!L40 -> 0 | L40: =+J40+K40 -> 0
E41: Ahorro | I41: =+AGOSTO!I41 -> 0 | J41: =+AGOSTO!L41 -> 0 | L41: =+J41+K41 -> 0
E42: Ocio | I42: =+AGOSTO!I42 -> 0 | J42: =+AGOSTO!L42 -> 0 | L42: =+J42+K42 -> 0
...

Sheet OCTUBRE
C1: =SUM(C3:C7) -> 0
B2: Ingresos | C2: =100%-C1 -> 1
B3: Fijos | C3: =+C11/C10 -> 0
B4: Variables | C4: =+C12/C10 -> 0
B5: Inversion | C5: =+C15/C10 -> 0
B6: Ocio | C6: =+C13/C10 -> 0
B7: Ahorro | C7: =+C14/C10 -> 0
B9: CONTROL DE OCTUBRE | I9: INGRESOS | J9: Intereses Recibidos
B10: Ingresos | C10: =+J16 -> 5000000 | J10: 5000000
B11: Fijos | C11: =+SUMIFS($G$20:$G$48,$E$20:$E$48,$B$11) -> 0
B12: Variables | C12: =+SUMIFS($G$20:$G$47,$E$20:$E$47,$B$12) -> 0
B13: Ocio | C13: =+SUMIFS($G$20:$G$48,$E$20:$E$48,$B$13) -> 0
B14: Ahorro | C14: =+SUMIFS($G$20:$G$48,$E$20:$E$48,$B$14) -> 0
B15: Inversion | C15: =+SUMIFS($G$20:$G$48,$E$20:$E$48,$B$15) -> 0
B16: Total Gastado | I16: TOTAL | J16: =+SUM(J10:J15) -> 5000000
B17: =+SUM(C11:C15) -> 0
B19: Fecha | C19: Medio de pago | D19: Descripción | E19: Categoría | F19: Presupuestado | G19: Gastado
E20: Fijos
E21: Fijos
E22: Ahorro | I22: Ahorro / Inversion | J22: Intereses Recibidos
E23: Fijos | I23: =+SEPTIEMBRE!I23 -> Trii
E24: Fijos | I24: =+SEPTIEMBRE!I24 -> Uala
E25: Fijos | I25: =+SEPTIEMBRE!I25 -> Nubank
E26: Fijos | I26: =+SEPTIEMBRE!I26 -> 0
E27: Fijos | I27: =+SEPTIEMBRE!I27 -> 0
E28: Fijos | I28: =+SEPTIEMBRE!I28 -> 0
E29: Fijos | I29: TOTAL | J29: =+SUM(J23:J28) -> 0
E30: Fijos
E31: Fijos
E32: Fijos
E33: Variables
E34: Ocio | I34: DEUDA | J34: VALOR | K34: PAGADO | L34: NUEVO VALOR
E35: Ahorro | I35: =+SEPTIEMBRE!I35 -> 0 | J35: =+SEPTIEMBRE!L35 -> 0 | L35: =+J35+K35 -> 0
E36: Ocio | I36: =+SEPTIEMBRE!I36 -> 0 | J36: =+SEPTIEMBRE!L36 -> 0 | L36: =+J36+K36 -> 0
E37: Fijos | I37: =+SEPTIEMBRE!I37 -> 0 | J37: =+SEPTIEMBRE!L37 -> 0 | L37: =+J37+K37 -> 0
E38: Inversion | I38: =+SEPTIEMBRE!I38 -> 0 | J38: =+SEPTIEMBRE!L38 -> 0 | L38: =+J38+K38 -> 0
E39: Variables | I39: =+SEPTIEMBRE!I39 -> 0 | J39: =+SEPTIEMBRE!L39 -> 0 | L39: =+J39+K39 -> 0
E40: Ocio | I40: =+SEPTIEMBRE!I40 -> 0 | J40: =+SEPTIEMBRE!L40 -> 0 | L40: =+J40+K40 -> 0
E41: Ahorro | I41: =+SEPTIEMBRE!I41 -> 0 | J41: =+SEPTIEMBRE!L41 -> 0 | L41: =+J41+K41 -> 0
E42: Ocio | I42: =+SEPTIEMBRE!I42 -> 0 | J42: =+SEPTIEMBRE!L42 -> 0 | L42: =+J42+K42 -> 0
...

Sheet NOVIEMBRE
C1: =SUM(C3:C7) -> 0
B2: Ingresos | C2: =100%-C1 -> 1
B3: Fijos | C3: =+C11/C10 -> 0
B4: Variables | C4: =+C12/C10 -> 0
B5: Inversion | C5: =+C15/C10 -> 0
B6: Ocio | C6: =+C13/C10 -> 0
B7: Ahorro | C7: =+C14/C10 -> 0
B9: CONTROL DE NOVIEMBRE | I9: INGRESOS | J9: Intereses Recibidos
B10: Ingresos | C10: =+J16 -> 5000000 | J10: 5000000
B11: Fijos | C11: =+SUMIFS($G$20:$G$48,$E$20:$E$48,$B$11) -> 0
B12: Variables | C12: =+SUMIFS($G$20:$G$47,$E$20:$E$47,$B$12) -> 0
B13: Ocio | C13: =+SUMIFS($G$20:$G$48,$E$20:$E$48,$B$13) -> 0
B14: Ahorro | C14: =+SUMIFS($G$20:$G$48,$E$20:$E$48,$B$14) -> 0
B15: Inversion | C15: =+SUMIFS($G$20:$G$48,$E$20:$E$48,$B$15) -> 0
B16: Total Gastado | I16: TOTAL | J16: =+SUM(J10:J15) -> 5000000
B17: =+SUM(C11:C15) -> 0
B19: Fecha | C19: Medio de pago | D19: Descripción | E19: Categoría | F19: Presupuestado | G19: Gastado
E20: Fijos
E21: Fijos
E22: Ahorro | I22: Ahorro / Inversion | J22: Intereses Recibidos
E23: Fijos | I23: =+OCTUBRE!I23 -> Trii
E24: Fijos | I24: =+OCTUBRE!I24 -> Uala
E25: Fijos | I25: =+OCTUBRE!I25 -> Nubank
E26: Fijos | I26: =+OCTUBRE!I26 -> 0
E27: Fijos | I27: =+OCTUBRE!I27 -> 0
E28: Fijos | I28: =+OCTUBRE!I28 -> 0
E29: Fijos | I29: TOTAL | J29: =+SUM(J23:J28) -> 0
E30: Fijos
E31: Fijos
E32: Fijos
E33: Variables
E34: Ocio | I34: DEUDA | J34: VALOR | K34: PAGADO | L34: NUEVO VALOR
E35: Ahorro | I35: =+OCTUBRE!I35 -> 0 | J35: =+OCTUBRE!L35 -> 0 | L35: =+J35+K35 -> 0
E36: Ocio | I36: =+OCTUBRE!I36 -> 0 | J36: =+OCTUBRE!L36 -> 0 | L36: =+J36+K36 -> 0
E37: Fijos | I37: =+OCTUBRE!I37 -> 0 | J37: =+OCTUBRE!L37 -> 0 | L37: =+J37+K37 -> 0
E38: Inversion | I38: =+OCTUBRE!I38 -> 0 | J38: =+OCTUBRE!L38 -> 0 | L38: =+J38+K38 -> 0
E39: Variables | I39: =+OCTUBRE!I39 -> 0 | J39: =+OCTUBRE!L39 -> 0 | L39: =+J39+K39 -> 0
E40: Ocio | I40: =+OCTUBRE!I40 -> 0 | J40: =+OCTUBRE!L40 -> 0 | L40: =+J40+K40 -> 0
E41: Ahorro | I41: =+OCTUBRE!I41 -> 0 | J41: =+OCTUBRE!L41 -> 0 | L41: =+J41+K41 -> 0
E42: Ocio | I42: =+OCTUBRE!I42 -> 0 | J42: =+OCTUBRE!L42 -> 0 | L42: =+J42+K42 -> 0
...

Sheet DICIEMBRE
C1: =SUM(C3:C7) -> 0
B2: Ingresos | C2: =100%-C1 -> 1
B3: Fijos | C3: =+C11/C10 -> 0
B4: Variables | C4: =+C12/C10 -> 0
B5: Inversion | C5: =+C15/C10 -> 0
B6: Ocio | C6: =+C13/C10 -> 0
B7: Ahorro | C7: =+C14/C10 -> 0
B9: CONTROL DE DICIEMBRE | I9: INGRESOS | J9: Intereses Recibidos
B10: Ingresos | C10: =+J16 -> 5000000 | J10: 5000000
B11: Fijos | C11: =+SUMIFS($G$20:$G$48,$E$20:$E$48,$B$11) -> 0
B12: Variables | C12: =+SUMIFS($G$20:$G$47,$E$20:$E$47,$B$12) -> 0
B13: Ocio | C13: =+SUMIFS($G$20:$G$48,$E$20:$E$48,$B$13) -> 0
B14: Ahorro | C14: =+SUMIFS($G$20:$G$48,$E$20:$E$48,$B$14) -> 0
B15: Inversion | C15: =+SUMIFS($G$20:$G$48,$E$20:$E$48,$B$15) -> 0
B16: Total Gastado | I16: TOTAL | J16: =+SUM(J10:J15) -> 5000000
B17: =+SUM(C11:C15) -> 0
B19: Fecha | C19: Medio de pago | D19: Descripción | E19: Categoría | F19: Presupuestado | G19: Gastado
E20: Fijos
E21: Fijos
E22: Ahorro | I22: Ahorro / Inversion | J22: Intereses Recibidos
E23: Fijos | I23: =+NOVIEMBRE!I23 -> Trii
E24: Fijos | I24: =+NOVIEMBRE!I24 -> Uala
E25: Fijos | I25: =+NOVIEMBRE!I25 -> Nubank
E26: Fijos | I26: =+NOVIEMBRE!I26 -> 0
E27: Fijos | I27: =+NOVIEMBRE!I27 -> 0
E28: Fijos | I28: =+NOVIEMBRE!I28 -> 0
E29: Fijos | I29: TOTAL | J29: =+SUM(J23:J28) -> 0
E30: Fijos
E31: Fijos
E32: Fijos
E33: Variables
E34: Ocio | I34: DEUDA | J34: VALOR | K34: PAGADO | L34: NUEVO VALOR
E35: Ahorro | I35: =+NOVIEMBRE!I35 -> 0 | J35: =+NOVIEMBRE!L35 -> 0 | L35: =+J35+K35 -> 0
E36: Ocio | I36: =+NOVIEMBRE!I36 -> 0 | J36: =+NOVIEMBRE!L36 -> 0 | L36: =+J36+K36 -> 0
E37: Fijos | I37: =+NOVIEMBRE!I37 -> 0 | J37: =+NOVIEMBRE!L37 -> 0 | L37: =+J37+K37 -> 0
E38: Inversion | I38: =+NOVIEMBRE!I38 -> 0 | J38: =+NOVIEMBRE!L38 -> 0 | L38: =+J38+K38 -> 0
E39: Variables | I39: =+NOVIEMBRE!I39 -> 0 | J39: =+NOVIEMBRE!L39 -> 0 | L39: =+J39+K39 -> 0
E40: Ocio | I40: =+NOVIEMBRE!I40 -> 0 | J40: =+NOVIEMBRE!L40 -> 0 | L40: =+J40+K40 -> 0
E41: Ahorro | I41: =+NOVIEMBRE!I41 -> 0 | J41: =+NOVIEMBRE!L41 -> 0 | L41: =+J41+K41 -> 0
E42: Ocio | I42: =+NOVIEMBRE!I42 -> 0 | J42: =+NOVIEMBRE!L42 -> 0 | L42: =+J42+K42 -> 0
...

Sheet RESUMEN ANUAL
B9: ENERO | C9: FEBRERO | D9: MARZO | E9: ABRIL | F9: MAYO | G9: JUNIO | H9: JULIO | I9: AGOSTO | J9: SEPTIEMBRE | K9: OCTUBRE | L9: NOVIEMBRE | M9: DICIEMBRE
A10: Ingresos | B10: =+ENERO!C10 -> 5000000 | C10: =+FEBRERO!C10 -> 5000000 | D10: =+MARZO!C10 -> 5000000 | E10: =+ABRIL!C10 -> 5000000 | F10: =+MAYO!C10 -> 5000000 | G10: =+JUNIO!C10 -> 5000000 | H10: =+JULIO!C10 -> 5000000 | I10: =+AGOSTO!C10 -> 5000000 | J10: =+SEPTIEMBRE!C10 -> 5000000 | K10: =+OCTUBRE!C10 -> 5000000 | L10: =+NOVIEMBRE!C10 -> 5000000 | M10: =+DICIEMBRE!C10 -> 5000000
A11: Egresos | B11: =+SUM(ENERO!C11:C13) -> 0 | C11: =+SUM(FEBRERO!C11:C13) -> 0 | D11: =+SUM(MARZO!C11:C13) -> 0 | E11: =+SUM(ABRIL!C11:C13) -> 0 | F11: =+SUM(MAYO!C11:C13) -> 0 | G11: =+SUM(JUNIO!C11:C13) -> 0 | H11: =+SUM(JULIO!C11:C13) -> 0 | I11: =+SUM(AGOSTO!C11:C13) -> 0 | J11: =+SUM(SEPTIEMBRE!C11:C13) -> 0 | K11: =+SUM(OCTUBRE!C11:C13) -> 0 | L11: =+SUM(NOVIEMBRE!C11:C13) -> 0 | M11: =+SUM(DICIEMBRE!C11:C13) -> 0
A12: Resultado por mes | B12: =B10-B11 -> 5000000 | C12: =C10-C11 -> 5000000 | D12: =D10-D11 -> 5000000 | E12: =E10-E11 -> 5000000 | F12: =F10-F11 -> 5000000 | G12: =G10-G11 -> 5000000 | H12: =H10-H11 -> 5000000 | I12: =I10-I11 -> 5000000 | ... M12: =M10-M11 -> 5000000
B14: ENERO | C14: FEBRERO | D14: MARZO | E14: ABRIL | F14: MAYO | G14: JUNIO | H14: JULIO | I14: AGOSTO | J14: SEPTIEMBRE | K14: OCTUBRE | L14: NOVIEMBRE | M14: DICIEMBRE
A15: Ahorro/Inversion | B15: =+SUM(ENERO!C14:C15) -> 0 | C15: =+B17+SUM(FEBRERO!C14:C15) -> 0 | D15: =C17+SUM(MARZO!C14:C15) -> 0 | E15: =D17+SUM(ABRIL!C14:C15) -> 0 | F15: =E17+SUM(MAYO!C14:C15) -> 0 | G15: =F17+SUM(JUNIO!C14:C15) -> 0 | H15: =G17+SUM(JULIO!C14:C15) -> 0 | I15: =H17+SUM(AGOSTO!C14:C15) -> 0 | J15: =I17+SUM(SEPTIEMBRE!C14:C15) -> 0 | K15: =J17+SUM(OCTUBRE!C14:C15) -> 0 | L15: =K17+SUM(NOVIEMBRE!C14:C15) -> 0 | M15: =L17+SUM(DICIEMBRE!C14:C15) -> 0
A16: Intereses recibidos | B16: =+ENERO!J29 -> 0 | C16: =+FEBRERO!J29 -> 0 | D16: =+MARZO!J29 -> 0 | E16: =+ABRIL!J29 -> 0 | F16: =+MAYO!J29 -> 0 | G16: =+JUNIO!J29 -> 0 | H16: =+JULIO!J29 -> 0 | I16: =+AGOSTO!J29 -> 0 | J16: =+SEPTIEMBRE!J29 -> 0 | K16: =+OCTUBRE!J29 -> 0 | L16: =+NOVIEMBRE!J29 -> 0 | M16: =+DICIEMBRE!J29 -> 0
A17: Resultado de la inversion | B17: =B15+B16 -> 0 | C17: =C15+C16 -> 0 | D17: =D15+D16 -> 0 | E17: =E15+E16 -> 0 | F17: =F15+F16 -> 0 | G17: =G15+G16 -> 0 | H17: =H15+H16 -> 0 | I17: =I15+I16 -> 0 | ... M17: =M15+M16 -> 0
B19: ENERO | C19: FEBRERO | D19: MARZO | E19: ABRIL | F19: MAYO | G19: JUNIO | H19: JULIO | I19: AGOSTO | J19: SEPTIEMBRE | K19: OCTUBRE | L19: NOVIEMBRE | M19: DICIEMBRE
A20: Deuda total | B20: =+ENERO!J44 -> 0 | C20: =+FEBRERO!J43 -> 0 | D20: =+MARZO!J43 -> 0 | E20: =+ABRIL!J43 -> 0 | F20: =+MAYO!J43 -> 0 | G20: =+JUNIO!J43 -> 0 | H20: =+JULIO!J43 -> 0 | I20: =+AGOSTO!J43 -> 0 | J20: =+SEPTIEMBRE!J43 -> 0 | K20: =+OCTUBRE!J43 -> 0 | L20: =+NOVIEMBRE!J43 -> 0 | M20: =+DICIEMBRE!J43 -> 0
A21: Pago de deuda | B21: =+ENERO!K44 -> 0 | C21: =+FEBRERO!K43 -> 0 | D21: =+MARZO!K43 -> 0 | E21: =+ABRIL!K43 -> 0 | F21: =+MAYO!K43 -> 0 | G21: =+JUNIO!K43 -> 0 | H21: =+JULIO!K43 -> 0 | I21: =+AGOSTO!K43 -> 0 | J21: =+SEPTIEMBRE!K43 -> 0 | K21: =+OCTUBRE!K43 -> 0 | L21: =+NOVIEMBRE!K43 -> 0 | M21: =+DICIEMBRE!K43 -> 0
A22: Resultado de deuda | B22: =+B20+B21 -> 0 | C22: =+C20+C21 -> 0 | D22: =+D20+D21 -> 0 | E22: =+E20+E21 -> 0 | F22: =+F20+F21 -> 0 | G22: =+G20+G21 -> 0 | H22: =+H20+H21 -> 0 | I22: =+I20+I21 -> 0 | ... M22: =+M20+M21 -> 0
A23: Comportamiento de deuda | B23: =+B22 -> 0 | C23: =-B22+C20+C22 -> 0 | D23: =-C22+D20+D22 -> 0 | E23: =-D22+E20+E22 -> 0 | F23: =-E22+F20+F22 -> 0 | G23: =-F22+G20+G22 -> 0 | H23: =-G22+H20+H22 -> 0 | I23: =-H22+I20+I22 -> 0 | J23: =-I22+J20+J22 -> 0 | ... M23: =-L22+M20+M22 -> 0

Sheet Listas
A1: Medio de Pago | C1: Gastos
A2: Tarjeta Davivienda | C2: Fijos
A3: Ahorros Davivienda | C3: Variables
A4: Nequi | C4: Ahorro
A5: Daviplata | C5: Inversion
A6: Nubank | C6: Ocio
A7: Uala
